Workbook

Sheet LibManager
A1: Operator | B1: nrOutTensors | C1: nrInTensors | D1: members | E1: templateElk | F1: extraImpl | G1: implSel
A2: AdaptiveAvgPool | B2: 1 | C2: 1 | E2: 1 | G2: default
A3: ArgMax | B3: 1 | C3: 1 | D3: Axis, KeepDims | E3: 0,1 | G3: default
A4: AvgPool | B4: 1 | C4: 1 | D4: Kernels, Strides, Pads,Layout,CountIncludePads | E4: 0 | F4: Threaded | G4: custom
A5: BatchOneHot | B5: 1 | C5: 3 | E5: 0 | G5: default
A6: BatchedAdd | B6: 1 | C6: 2 | E6: 0,1,2 | G6: default
A7: BatchedReduceAdd | B7: 1 | C7: 1 | D7: Axis | E7: 1 | G7: default
A8: ConvertTo | B8: 1 | C8: 1 | E8: 0,1 | F8: Vectorized | G8: default
A9: Convolution | B9: 1 | C9: 3 | D9: Kernels, Strides, Pads, Group, Dilation, FusedActivation, FusedActivationArgs | E9: 0,3 | F9: Vectorized | G9: custom
A10: Convolution3D | B10: 1 | C10: 3 | D10: Kernels, Strides, Pads, Group | E10: 0 | G10: default
A11: Copy | B11: 1 | C11: 1 | E11: 0 | F11: Tensorized | G11: custom
A12: CrossEntropyLoss | B12: 1 | C12: 2 | E12: 1 | G12: default
A13: Dequantize | B13: 1 | C13: 1 | E13: 0,1 | G13: default
A14: ElementAdd | B14: 1 | C14: 2 | E14: 0 | G14: default
A15: ElementCmpEQ | B15: 1 | C15: 2 | E15: 1,2 | F15: Vectorized | G15: custom
A16: ElementCmpLT | B16: 1 | C16: 2 | E16: 1,2 | F16: Vectorized | G16: custom
A17: ElementCmpLTE | B17: 1 | C17: 2 | E17: 1,2 | F17: Vectorized | G17: custom
A18: ElementDiv | B18: 1 | C18: 2 | E18: 0 | G18: default
A19: ElementExp | B19: 1 | C19: 1 | E19: 1 | G19: default
A20: ElementIsNaN | B20: 1 | C20: 1 | E20: 1 | G20: default
A21: ElementLog | B21: 1 | C21: 1 | E21: 0,1 | G21: default
A22: ElementMax | B22: 1 | C22: 2 | E22: 0 | G22: default
A23: ElementMin | B23: 1 | C23: 2 | E23: 0 | G23: default
A24: ElementMul | B24: 1 | C24: 2 | E24: 0 | G24: default
A25: ElementPow | B25: 1 | C25: 2 | E25: 0 | G25: default
A26: ElementSelect | B26: 1 | C26: 3 | E26: 0 | G26: default
A27: ElementSub | B27: 1 | C27: 2 | E27: 0 | G27: default
A28: EmbeddingBag | B28: 1 | C28: 4 | D28: HasEndOffset | E28: 0 | G28: default
A29: ExtractTensor | B29: 1 | C29: 1 | D29: Offsets | E29: 1 | G29: default
A30: Flip | B30: 1 | C30: 1 | D30: Axis | E30: 1 | G30: default
A31: FullyConnected | B31: 1 | C31: 3 | E31: 0,3 | G31: default
A32: FusedRowwiseQuantizedSparseLengthsSum | B32: 1 | C32: 3 | E32: 0 | G32: default
A33: FusedRowwiseQuantizedSparseLengthsWeightedSum | B33: 1 | C33: 4 | E33: 0 | G33: default
A34: Gather | B34: 1 | C34: 2 | D34: BatchDims | E34: 1,2 | G34: default
A35: GatherRanges | B35: 2 | C35: 2 | E35: 2,3 | G35: default
A36: InsertTensor | B36: 1 | C36: 1 | D36: Offsets, Count,Axis | E36: 1 | F36: Threaded | G36: custom
A37: Int8Converter | B37: 1 | C37: 1 | E37: 1 | G37: default
A38: IntLookupTable | B38: 1 | C38: 2 | E38: NONE | G38: default
A39: LengthsSum | B39: 1 | C39: 2 | E39: 1 | G39: default
A40: LengthsToRanges | B40: 1 | C40: 1 | E40: 1 | G40: default
...

Sheet Instances
A1: Operator | B1: nrOutTensors | C1: nrInTensors | D1: templateElk
A2: =LibManager!A2 -> AdaptiveAvgPool | B2: =LibManager!B2 -> 1 | C2: =LibManager!C2 -> 1 | D2: 1 | E2: FloatTy | F2: Float16Ty | G2: Int8QTy | H2: Int64ITy | I2: Int32ITy | J2: Int16QTy
A3: =LibManager!A3 -> ArgMax | B3: =LibManager!B3 -> 1 | C3: =LibManager!C3 -> 1 | D3: 1 | E3: Int64ITy,FloatTy | F3: Int32ITy,FloatTy | G3: Int64ITy,Int8QTy | H3: Int32ITy,Int8QTy
A4: =LibManager!A4 -> AvgPool | B4: =LibManager!B4 -> 1 | C4: =LibManager!C4 -> 1 | D4: 0 | E4: FloatTy | F4: Float16Ty | G4: Int8QTy
A5: =LibManager!A5 -> BatchOneHot | B5: =LibManager!B5 -> 1 | C5: =LibManager!C5 -> 3 | D5: 0 | E5: FloatTy | F5: Float16Ty | G5: Int8QTy | H5: Int64ITy | I5: Int32ITy | J5: Int16QTy
A6: =LibManager!A6 -> BatchedAdd | B6: =LibManager!B6 -> 1 | C6: =LibManager!C6 -> 2 | D6: 0,1,2 | E6: FloatTy,FloatTy,FloatTy | F6: Float16Ty,Float16Ty,Float16Ty | G6: Int8QTy,Int8QTy,Int8QTy | H6: Int8QTy,Int8QTy,Int32QTy | I6: Int16QTy,Int16QTy,Int16QTy | J6: Int16QTy,Int16QTy,Int32QTy
A7: =LibManager!A7 -> BatchedReduceAdd | B7: =LibManager!B7 -> 1 | C7: =LibManager!C7 -> 1 | D7: 1 | E7: FloatTy | F7: Float16Ty | G7: Int8QTy | H7: Int64ITy | I7: Int32ITy | J7: Int16QTy
A8: =LibManager!A8 -> ConvertTo | B8: =LibManager!B8 -> 1 | C8: =LibManager!C8 -> 1 | D8: 0,1 | E8: Float16Ty,FloatTy | F8: Float16Ty,Int32ITy | G8: Float16Ty,Int64ITy | H8: FloatTy,Float16Ty | I8: FloatTy,Int32ITy | J8: FloatTy,Int64ITy | K8: Int32ITy,Float16Ty | L8: Int32ITy,FloatTy | M8: Int32ITy,Int64ITy | N8: Int64ITy,Float16Ty | O8: Int64ITy,FloatTy | P8: Int64ITy,Int32ITy | Q8: FloatTy,BoolTy | R8: Float16Ty,BoolTy | S8: Int64ITy,BoolTy | T8: Int32ITy,BoolTy | U8: BoolTy,FloatTy | V8: BoolTy,Float16Ty | W8: BoolTy,Int64ITy | X8: BoolTy,Int32ITy | Y8: BoolTy,BoolTy
A9: =LibManager!A9 -> Convolution | B9: =LibManager!B9 -> 1 | C9: =LibManager!C9 -> 3 | D9: 0,3 | E9: FloatTy,FloatTy | F9: Float16Ty,Float16Ty | G9: Int8QTy,Int8QTy | H9: Int8QTy,Int32QTy | I9: Int16QTy,Int16QTy | J9: Int16QTy,Int32QTy
A10: =LibManager!A10 -> Convolution3D | B10: =LibManager!B10 -> 1 | C10: =LibManager!C10 -> 3 | D10: 0 | E10: FloatTy | F10: Float16Ty | G10: Int8QTy | H10: Int64ITy | I10: Int32ITy | J10: Int16QTy
A11: =LibManager!A11 -> Copy | B11: =LibManager!B11 -> 1 | C11: =LibManager!C11 -> 1 | D11: 0 | E11: FloatTy | F11: Float16Ty | G11: Int8QTy | H11: Int64ITy | I11: Int32ITy | J11: Int16QTy
A12: =LibManager!A12 -> CrossEntropyLoss | B12: =LibManager!B12 -> 1 | C12: =LibManager!C12 -> 2 | D12: 1 | E12: FloatTy | F12: Float16Ty | G12: Int8QTy | H12: Int64ITy | I12: Int32ITy | J12: Int16QTy
A13: =LibManager!A13 -> Dequantize | B13: =LibManager!B13 -> 1 | C13: =LibManager!C13 -> 1 | D13: 0,1 | E13: FloatTy,Int8QTy | F13: FloatTy,UInt8QTy | G13: FloatTy,Int16QTy | H13: FloatTy,Int32QTy | I13: Float16Ty,Int8QTy | J13: Float16Ty,UInt8QTy | K13: Float16Ty,Int16QTy | L13: Float16Ty,Int32QTy
A14: =LibManager!A14 -> ElementAdd | B14: =LibManager!B14 -> 1 | C14: =LibManager!C14 -> 2 | D14: 0 | E14: FloatTy | F14: Float16Ty | G14: Int8QTy | H14: Int32ITy | I14: Int64ITy
A15: =LibManager!A15 -> ElementCmpEQ | B15: =LibManager!B15 -> 1 | C15: =LibManager!C15 -> 2 | D15: 1,2 | E15: FloatTy,FloatTy | F15: Float16Ty,Float16Ty | G15: Int8QTy,Int8QTy | H15: Int32ITy,Int32ITy | I15: Int64ITy,Int64ITy
A16: =LibManager!A16 -> ElementCmpLT | B16: =LibManager!B16 -> 1 | C16: =LibManager!C16 -> 2 | D16: 1,2 | E16: FloatTy,FloatTy | F16: Float16Ty,Float16Ty | G16: Int8QTy,Int8QTy | H16: Int32ITy,Int32ITy | I16: Int64ITy,Int64ITy
A17: =LibManager!A17 -> ElementCmpLTE | B17: =LibManager!B17 -> 1 | C17: =LibManager!C17 -> 2 | D17: 1,2 | E17: FloatTy,FloatTy | F17: Float16Ty,Float16Ty | G17: Int8QTy,Int8QTy | H17: Int32ITy,Int32ITy | I17: Int64ITy,Int64ITy
A18: =LibManager!A18 -> ElementDiv | B18: =LibManager!B18 -> 1 | C18: =LibManager!C18 -> 2 | D18: 0 | E18: FloatTy | F18: Float16Ty | G18: Int8QTy | H18: Int64ITy
A19: =LibManager!A19 -> ElementExp | B19: =LibManager!B19 -> 1 | C19: =LibManager!C19 -> 1 | D19: 1 | E19: FloatTy | F19: Float16Ty
A20: =LibManager!A20 -> ElementIsNaN | B20: =LibManager!B20 -> 1 | C20: =LibManager!C20 -> 1 | D20: 1 | E20: FloatTy | F20: Float16Ty
A21: =LibManager!A21 -> ElementLog | B21: =LibManager!B21 -> 1 | C21: =LibManager!C21 -> 1 | D21: 0,1 | E21: FloatTy,FloatTy | F21: Float16Ty,Float16Ty
A22: =LibManager!A22 -> ElementMax | B22: =LibManager!B22 -> 1 | C22: =LibManager!C22 -> 2 | D22: 0 | E22: FloatTy | F22: Float16Ty | G22: Int8QTy | H22: Int32ITy | I22: Int64ITy
A23: =LibManager!A23 -> ElementMin | B23: =LibManager!B23 -> 1 | C23: =LibManager!C23 -> 2 | D23: 0 | E23: FloatTy | F23: Float16Ty | G23: Int8QTy | H23: Int32ITy | I23: Int64ITy
A24: =LibManager!A24 -> ElementMul | B24: =LibManager!B24 -> 1 | C24: =LibManager!C24 -> 2 | D24: 0 | E24: FloatTy | F24: Float16Ty | G24: Int8QTy | H24: Int32ITy | I24: Int64ITy
A25: =LibManager!A25 -> ElementPow | B25: =LibManager!B25 -> 1 | C25: =LibManager!C25 -> 2 | D25: 0 | E25: FloatTy | F25: Float16Ty
A26: =LibManager!A26 -> ElementSelect | B26: =LibManager!B26 -> 1 | C26: =LibManager!C26 -> 3 | D26: 0 | E26: FloatTy | F26: Float16Ty | G26: Int8QTy | H26: Int64ITy | I26: Int32ITy | J26: Int16QTy
A27: =LibManager!A27 -> ElementSub | B27: =LibManager!B27 -> 1 | C27: =LibManager!C27 -> 2 | D27: 0 | E27: FloatTy | F27: Float16Ty | G27: Int8QTy | H27: Int32ITy | I27: Int64ITy
A28: =LibManager!A28 -> EmbeddingBag | B28: =LibManager!B28 -> 1 | C28: =LibManager!C28 -> 4 | D28: 0 | E28: FloatTy | F28: Float16Ty
A29: =LibManager!A29 -> ExtractTensor | B29: =LibManager!B29 -> 1 | C29: =LibManager!C29 -> 1 | D29: 1 | E29: FloatTy | F29: Float16Ty | G29: Int8QTy | H29: Int64ITy | I29: Int32ITy | J29: Int16QTy
A30: =LibManager!A30 -> Flip | B30: =LibManager!B30 -> 1 | C30: =LibManager!C30 -> 1 | D30: 1 | E30: FloatTy | F30: Float16Ty | G30: Int8QTy | H30: Int64ITy | I30: Int32ITy | J30: Int16QTy | K30: Int32QTy
A31: =LibManager!A31 -> FullyConnected | B31: =LibManager!B31 -> 1 | C31: =LibManager!C31 -> 3 | D31: 0,3 | E31: FloatTy,FloatTy | F31: Float16Ty,Float16Ty | G31: Int8QTy,Int8QTy | H31: Int8QTy,Int32QTy | I31: Int8QTy,FloatTy | J31: Int16QTy,Int16QTy | K31: Int16QTy,Int32QTy
A32: =LibManager!A32 -> FusedRowwiseQuantizedSparseLengthsSum | B32: =LibManager!B32 -> 1 | C32: =LibManager!C32 -> 3 | D32: 0 | E32: FloatTy | F32: Float16Ty
A33: =LibManager!A33 -> FusedRowwiseQuantizedSparseLengthsWeightedSum | B33: =LibManager!B33 -> 1 | C33: =LibManager!C33 -> 4 | D33: 0 | E33: FloatTy | F33: #Float16Ty
A34: =LibManager!A34 -> Gather | B34: =LibManager!B34 -> 1 | C34: =LibManager!C34 -> 2 | D34: 1,2 | E34: FloatTy,Int32ITy | F34: Float16Ty,Int32ITy | G34: Int8QTy,Int32ITy | H34: UInt8QTy,Int32ITy | I34: Int16QTy,Int32ITy | J34: FloatTy,Int64ITy | K34: Float16Ty,Int64ITy | L34: Int8QTy,Int64ITy | M34: UInt8QTy,Int64ITy | N34: Int16QTy,Int64ITy
A35: =LibManager!A35 -> GatherRanges | B35: =LibManager!B35 -> 2 | C35: =LibManager!C35 -> 2 | D35: 2,3 | E35: FloatTy,Int32ITy | F35: Float16Ty,Int32ITy | G35: Int8QTy,Int32ITy | H35: UInt8QTy,Int32ITy | I35: Int16QTy,Int32ITy | J35: FloatTy,Int64ITy | K35: Float16Ty,Int64ITy | L35: Int8QTy,Int64ITy | M35: UInt8QTy,Int64ITy | N35: Int16QTy,Int64ITy
A36: =LibManager!A36 -> InsertTensor | B36: =LibManager!B36 -> 1 | C36: =LibManager!C36 -> 1 | D36: 1 | E36: FloatTy | F36: Float16Ty | G36: Int8QTy | H36: Int64ITy | I36: Int32ITy | J36: Int16QTy
A37: =LibManager!A37 -> Int8Converter | B37: =LibManager!B37 -> 1 | C37: =LibManager!C37 -> 1 | D37: 1 | E37: Int8QTy | F37: Int64ITy
A38: =LibManager!A38 -> IntLookupTable | B38: =LibManager!B38 -> 1 | C38: =LibManager!C38 -> 2 | D38: NONE
A39: =LibManager!A39 -> LengthsSum | B39: =LibManager!B39 -> 1 | C39: =LibManager!C39 -> 2 | D39: 1 | E39: FloatTy | F39: Float16Ty | G39: Int8QTy | H39: Int64ITy | I39: Int32ITy | J39: Int16QTy
A40: =LibManager!A40 -> LengthsToRanges | B40: =LibManager!B40 -> 1 | C40: =LibManager!C40 -> 1 | D40: 1 | E40: FloatTy | F40: Float16Ty | G40: Int8QTy | H40: Int64ITy | I40: Int32ITy | J40: Int16QTy
...
